Workbook

Sheet 1_Container_Calculator
A1: PRECISE PIPE — 40GP CONTAINER LOADING & COMMERCIAL ESTIMATOR MODEL
A2: Interactive Calculator & Schedule Matrix | Select Pipe Size (NPS), Schedule & Material in Yellow Cells (Col D) | ASME B36.10M (CS) & B36.19M (SS)
A4: 1. PIPE SPECIFICATION INPUTS (SELECT DROPDOWNS) | G4: OUTPUT 1: 40GP TOTAL PIECES | J4: OUTPUT 2: 40GP METRIC TONS (MT) | M4: BOTTLENECK & FREIGHT
A5: Material Grade [Select] | D5: Carbon Steel (CS) | G5: =IF(ISNUMBER(I12), M16, 0) | J5: =IF(ISNUMBER(I12), M17, 0) | M5: =IF(G5=0, "N/A", IF(M15<=M14, "WEIGHT LIMITED", "VOLUME LIMITED"))
A6: Nominal Pipe Size - NPS [Select] | D6: 6''
A7: Pipe Schedule [Select] | D7: 40 | M7: =IF(J5>0, "Freight: $" & TEXT(D17/J5, "#,##0.00") & " / MT", "Freight: N/A")
A8: Single Pipe Length (m) [Select] | D8: 11.8 | G8: ="Total Length: " & TEXT(G5*D8, "#,##0.0") & " m (" & TEXT(G5*D8*3.28084, "#,##0") & " ft)" | J8: ="Net Weight: " & TEXT(J5*1000, "#,##0") & " kg (" & TEXT(J5*2204.62, "#,##0") & " lbs)" | M8: =IF(G5>0, "Unit Freight: $" & TEXT(D17/(G5*D8), "0.00") & " / m", "Unit Freight: N/A")
A9: ASME Spec Status | D9: =IF(ISNUMBER(I12), "VALID ASME SPEC", "SCHEDULE N/A FOR THIS NPS (SEE TABLE BELOW)")
G10: 3. SELECTED PIPE PHYSICAL SPECS (ASME) | K10: 4. 40GP CONTAINER PACKING GEOMETRY
A11: 2. 40GP CONTAINER & COMMERCIAL PARAMETERS | G11: Outer Diameter - OD (mm) | I11: =IFERROR(INDEX('3_ASME_Spec_DB'!$D$12:$D$47, MATCH(D6, '3_ASME_Spec_DB'!$A$12:$A$47, 0)), 0) | K11: Lengthwise Tiers in 40GP | M11: =INT(D12 / D8)
A12: 40GP Internal Length (m) | D12: 12.032 | G12: Wall Thickness - WT (mm) | I12: =IFERROR(INDEX('3_ASME_Spec_DB'!$E$12:$V$47, MATCH(D6, '3_ASME_Spec_DB'!$A$12:$A$47, 0), MATCH("Sch "&D7, '3_ASME_Spec_DB'!$E$11:$V$11, 0)), "N/A") | K12: Bottom Row Fit (pcs / row) | M12: =IF(I11>0, INT(D13 / I11), 0)
A13: Effective Loading Width (mm) [Input] | D13: 2300 | G13: Outer / Wall (Inches) | I13: =TEXT(I11/25.4,"0.000") & " in OD x " & IF(ISNUMBER(I12), TEXT(I12/25.4,"0.000") & " in WT", "N/A") | K13: Vertical Stacked Layers | M13: =IF(M12=0, 0, IF(OR(D16="Square Grid", M12=1), INT(D14/I11), IF(D14<I11, 0, 1+INT((D14-I11)/(0.8660254*I11)))))
A14: Effective Loading Height (mm) [Input] | D14: 2280 | G14: Inner Diameter - ID (mm) | I14: =IF(ISNUMBER(I12), ROUND(I11 - 2*I12, 2), "N/A") | K14: Max Pieces by Volume (pcs) | M14: =IF(OR(M12=0,M13=0), 0, IF(OR(D16="Square Grid", M12=1), M12*M13*M11, (INT((M13+1)/2)*M12 + INT(M13/2)*IF((D13-M12*I11)>=0.5*I11, M12, M12-1))*M11))
A15: Max Container Payload (MT) [Input] | D15: 26 | G15: Material Weight Factor C | I15: =IF(D5="Carbon Steel (CS)", '3_ASME_Spec_DB'!D6, IF(D5="Stainless Steel 304 (SS304)", '3_ASME_Spec_DB'!D7, '3_ASME_Spec_DB'!D8)) | K15: Max Pieces by Weight (pcs) | M15: =IF(I18>0, INT((D15*1000) / I18), 0)
A16: Cross-Section Packing Mode [Select] | D16: Staggered (Hexagonal) | G16: Linear Unit Weight (kg/m) | I16: =IF(ISNUMBER(I12), ROUND((I11 - I12) * I12 * I15, 3), 0) | K16: 40GP Actual Loaded Pieces | M16: =IF(ISNUMBER(I12), MIN(M14, M15), 0)
A17: Est. Ocean Freight / 40GP (USD) [Input] | D17: 3500 | G17: Linear Unit Weight (lb/ft) | I17: =IF(ISNUMBER(I12), ROUND(I16 * 0.671969, 3), 0) | K17: 40GP Actual Net Weight (MT) | M17: =ROUND((M16 * I18) / 1000, 2)
A18: Nested Pipe Clearance Margin (mm) | D18: 25 | G18: Single Pipe Weight (kg/pc) | I18: =IF(ISNUMBER(I12), ROUND(I16 * D8, 2), 0) | K18: Weight Util. / Space Slot Util. | M18: =TEXT(IF(D15>0, M17/D15, 0), "0.0%") & " Wt | " & TEXT(IF(M14>0, M16/M14, 0), "0.0%") & " Space"
A20: =IF(NOT(ISNUMBER(I12)), "COMMERCIAL ADVISOR: Selected Schedule (" & D7 & ") is not standard for NPS " & D6 & ". Review the live table below for all valid Schedules for NPS " & D6 & ".", IF(M15<=M14, "COMMERCIAL ADVISOR [WEIGHT LIMITED]: Container reaches Max Payload (" & TEXT(M17,"0.00") & " MT) at " & TEXT(M16/M14,"0.0%") & " space occupancy. Increasing container weight limit or using lighter wall schedule increases piece count per box.", IF(I14>80, "COMMERCIAL ADVISOR [VOLUME LIMITED — PIPE NESTING OPPORTUNITY]: Space is 100% full at only " & TEXT(M17,"0.00") & " MT (" & TEXT(D15-M17,"0.00") & " MT unused payload!). Inner Diameter is " & TEXT(I14,"0.0") & " mm -> You can telescope/nest smaller pipes (OD <= " & TEXT(I14-D18,"0") & " mm) inside each pipe to ship extra tonnage for FREE ocean freight!", "COMMERCIAL ADVISOR [VOLUME LIMITED]: Container space is 100% utilized (" & TEXT(M16,"#,##0") & " pcs / " & TEXT(M17,"0.00") & " MT).")))
A22: ="5. ALL PIPE SCHEDULES COMPARISON MATRIX FOR SELECTED SIZE: NPS " & D6 & " (" & D5 & " | Pipe Length: " & TEXT(D8,"0.00") & "m)"
A23: Schedule | B23: Spec Status | C23: OD (mm) | D23: WT (in) | E23: WT (mm) | F23: ID (mm) | G23: Unit Wt (kg/m) | H23: Piece Wt (kg/pc) | I23: Max Pieces (Volume) | J23: Max Pieces (Weight) | K23: 40GP Actual Pieces (pcs) | L23: 40GP Actual Metric Tons (MT) | M23: Payload Util. (%) | N23: Limiting Factor (Bottleneck)
A24: 5S | B24: =IF(ISNUMBER(E24), "Available", "N/A") | C24: =IF(ISNUMBER(E24), $I$11, "-") | D24: =IF(ISNUMBER(E24), ROUND(E24/25.4, 3), "-") | E24: =IFERROR(INDEX('3_ASME_Spec_DB'!$E$12:$E$47, MATCH($D$6, '3_ASME_Spec_DB'!$A$12:$A$47, 0)), "-") | F24: =IF(ISNUMBER(E24), ROUND(C24-2*E24, 2), "-") | G24: =IF(ISNUMBER(E24), ROUND((C24-E24)*E24*$I$15, 3), "-") | H24: =IF(ISNUMBER(E24), ROUND(G24*$D$8, 2), "-") | I24: =IF(ISNUMBER(E24), $M$14, "-") | J24: =IF(ISNUMBER(E24), INT(($D$15*1000)/H24), "-") | K24: =IF(ISNUMBER(E24), MIN(I24, J24), "-") | L24: =IF(ISNUMBER(E24), ROUND((K24*H24)/1000, 2), "-") | M24: =IF(ISNUMBER(E24), L24/$D$15, "-") | N24: =IF(NOT(ISNUMBER(E24)), "-", IF(J24<=I24, "Weight Limited", "Volume Limited"))
A25: 5 | B25: =IF(ISNUMBER(E25), "Available", "N/A") | C25: =IF(ISNUMBER(E25), $I$11, "-") | D25: =IF(ISNUMBER(E25), ROUND(E25/25.4, 3), "-") | E25: =IFERROR(INDEX('3_ASME_Spec_DB'!$F$12:$F$47, MATCH($D$6, '3_ASME_Spec_DB'!$A$12:$A$47, 0)), "-") | F25: =IF(ISNUMBER(E25), ROUND(C25-2*E25, 2), "-") | G25: =IF(ISNUMBER(E25), ROUND((C25-E25)*E25*$I$15, 3), "-") | H25: =IF(ISNUMBER(E25), ROUND(G25*$D$8, 2), "-") | I25: =IF(ISNUMBER(E25), $M$14, "-") | J25: =IF(ISNUMBER(E25), INT(($D$15*1000)/H25), "-") | K25: =IF(ISNUMBER(E25), MIN(I25, J25), "-") | L25: =IF(ISNUMBER(E25), ROUND((K25*H25)/1000, 2), "-") | M25: =IF(ISNUMBER(E25), L25/$D$15, "-") | N25: =IF(NOT(ISNUMBER(E25)), "-", IF(J25<=I25, "Weight Limited", "Volume Limited"))
A26: 10S | B26: =IF(ISNUMBER(E26), "Available", "N/A") | C26: =IF(ISNUMBER(E26), $I$11, "-") | D26: =IF(ISNUMBER(E26), ROUND(E26/25.4, 3), "-") | E26: =IFERROR(INDEX('3_ASME_Spec_DB'!$G$12:$G$47, MATCH($D$6, '3_ASME_Spec_DB'!$A$12:$A$47, 0)), "-") | F26: =IF(ISNUMBER(E26), ROUND(C26-2*E26, 2), "-") | G26: =IF(ISNUMBER(E26), ROUND((C26-E26)*E26*$I$15, 3), "-") | H26: =IF(ISNUMBER(E26), ROUND(G26*$D$8, 2), "-") | I26: =IF(ISNUMBER(E26), $M$14, "-") | J26: =IF(ISNUMBER(E26), INT(($D$15*1000)/H26), "-") | K26: =IF(ISNUMBER(E26), MIN(I26, J26), "-") | L26: =IF(ISNUMBER(E26), ROUND((K26*H26)/1000, 2), "-") | M26: =IF(ISNUMBER(E26), L26/$D$15, "-") | N26: =IF(NOT(ISNUMBER(E26)), "-", IF(J26<=I26, "Weight Limited", "Volume Limited"))
A27: 10 | B27: =IF(ISNUMBER(E27), "Available", "N/A") | C27: =IF(ISNUMBER(E27), $I$11, "-") | D27: =IF(ISNUMBER(E27), ROUND(E27/25.4, 3), "-") | E27: =IFERROR(INDEX('3_ASME_Spec_DB'!$H$12:$H$47, MATCH($D$6, '3_ASME_Spec_DB'!$A$12:$A$47, 0)), "-") | F27: =IF(ISNUMBER(E27), ROUND(C27-2*E27, 2), "-") | G27: =IF(ISNUMBER(E27), ROUND((C27-E27)*E27*$I$15, 3), "-") | H27: =IF(ISNUMBER(E27), ROUND(G27*$D$8, 2), "-") | I27: =IF(ISNUMBER(E27), $M$14, "-") | J27: =IF(ISNUMBER(E27), INT(($D$15*1000)/H27), "-") | K27: =IF(ISNUMBER(E27), MIN(I27, J27), "-") | L27: =IF(ISNUMBER(E27), ROUND((K27*H27)/1000, 2), "-") | M27: =IF(ISNUMBER(E27), L27/$D$15, "-") | N27: =IF(NOT(ISNUMBER(E27)), "-", IF(J27<=I27, "Weight Limited", "Volume Limited"))
A28: 20 | B28: =IF(ISNUMBER(E28), "Available", "N/A") | C28: =IF(ISNUMBER(E28), $I$11, "-") | D28: =IF(ISNUMBER(E28), ROUND(E28/25.4, 3), "-") | E28: =IFERROR(INDEX('3_ASME_Spec_DB'!$I$12:$I$47, MATCH($D$6, '3_ASME_Spec_DB'!$A$12:$A$47, 0)), "-") | F28: =IF(ISNUMBER(E28), ROUND(C28-2*E28, 2), "-") | G28: =IF(ISNUMBER(E28), ROUND((C28-E28)*E28*$I$15, 3), "-") | H28: =IF(ISNUMBER(E28), ROUND(G28*$D$8, 2), "-") | I28: =IF(ISNUMBER(E28), $M$14, "-") | J28: =IF(ISNUMBER(E28), INT(($D$15*1000)/H28), "-") | K28: =IF(ISNUMBER(E28), MIN(I28, J28), "-") | L28: =IF(ISNUMBER(E28), ROUND((K28*H28)/1000, 2), "-") | M28: =IF(ISNUMBER(E28), L28/$D$15, "-") | N28: =IF(NOT(ISNUMBER(E28)), "-", IF(J28<=I28, "Weight Limited", "Volume Limited"))
A29: 30 | B29: =IF(ISNUMBER(E29), "Available", "N/A") | C29: =IF(ISNUMBER(E29), $I$11, "-") | D29: =IF(ISNUMBER(E29), ROUND(E29/25.4, 3), "-") | E29: =IFERROR(INDEX('3_ASME_Spec_DB'!$J$12:$J$47, MATCH($D$6, '3_ASME_Spec_DB'!$A$12:$A$47, 0)), "-") | F29: =IF(ISNUMBER(E29), ROUND(C29-2*E29, 2), "-") | G29: =IF(ISNUMBER(E29), ROUND((C29-E29)*E29*$I$15, 3), "-") | H29: =IF(ISNUMBER(E29), ROUND(G29*$D$8, 2), "-") | I29: =IF(ISNUMBER(E29), $M$14, "-") | J29: =IF(ISNUMBER(E29), INT(($D$15*1000)/H29), "-") | K29: =IF(ISNUMBER(E29), MIN(I29, J29), "-") | L29: =IF(ISNUMBER(E29), ROUND((K29*H29)/1000, 2), "-") | M29: =IF(ISNUMBER(E29), L29/$D$15, "-") | N29: =IF(NOT(ISNUMBER(E29)), "-", IF(J29<=I29, "Weight Limited", "Volume Limited"))
A30: 40S | B30: =IF(ISNUMBER(E30), "Available", "N/A") | C30: =IF(ISNUMBER(E30), $I$11, "-") | D30: =IF(ISNUMBER(E30), ROUND(E30/25.4, 3), "-") | E30: =IFERROR(INDEX('3_ASME_Spec_DB'!$K$12:$K$47, MATCH($D$6, '3_ASME_Spec_DB'!$A$12:$A$47, 0)), "-") | F30: =IF(ISNUMBER(E30), ROUND(C30-2*E30, 2), "-") | G30: =IF(ISNUMBER(E30), ROUND((C30-E30)*E30*$I$15, 3), "-") | H30: =IF(ISNUMBER(E30), ROUND(G30*$D$8, 2), "-") | I30: =IF(ISNUMBER(E30), $M$14, "-") | J30: =IF(ISNUMBER(E30), INT(($D$15*1000)/H30), "-") | K30: =IF(ISNUMBER(E30), MIN(I30, J30), "-") | L30: =IF(ISNUMBER(E30), ROUND((K30*H30)/1000, 2), "-") | M30: =IF(ISNUMBER(E30), L30/$D$15, "-") | N30: =IF(NOT(ISNUMBER(E30)), "-", IF(J30<=I30, "Weight Limited", "Volume Limited"))
A31: STD | B31: =IF(ISNUMBER(E31), "Available", "N/A") | C31: =IF(ISNUMBER(E31), $I$11, "-") | D31: =IF(ISNUMBER(E31), ROUND(E31/25.4, 3), "-") | E31: =IFERROR(INDEX('3_ASME_Spec_DB'!$L$12:$L$47, MATCH($D$6, '3_ASME_Spec_DB'!$A$12:$A$47, 0)), "-") | F31: =IF(ISNUMBER(E31), ROUND(C31-2*E31, 2), "-") | G31: =IF(ISNUMBER(E31), ROUND((C31-E31)*E31*$I$15, 3), "-") | H31: =IF(ISNUMBER(E31), ROUND(G31*$D$8, 2), "-") | I31: =IF(ISNUMBER(E31), $M$14, "-") | J31: =IF(ISNUMBER(E31), INT(($D$15*1000)/H31), "-") | K31: =IF(ISNUMBER(E31), MIN(I31, J31), "-") | L31: =IF(ISNUMBER(E31), ROUND((K31*H31)/1000, 2), "-") | M31: =IF(ISNUMBER(E31), L31/$D$15, "-") | N31: =IF(NOT(ISNUMBER(E31)), "-", IF(J31<=I31, "Weight Limited", "Volume Limited"))
A32: 40 | B32: =IF(ISNUMBER(E32), "Available", "N/A") | C32: =IF(ISNUMBER(E32), $I$11, "-") | D32: =IF(ISNUMBER(E32), ROUND(E32/25.4, 3), "-") | E32: =IFERROR(INDEX('3_ASME_Spec_DB'!$M$12:$M$47, MATCH($D$6, '3_ASME_Spec_DB'!$A$12:$A$47, 0)), "-") | F32: =IF(ISNUMBER(E32), ROUND(C32-2*E32, 2), "-") | G32: =IF(ISNUMBER(E32), ROUND((C32-E32)*E32*$I$15, 3), "-") | H32: =IF(ISNUMBER(E32), ROUND(G32*$D$8, 2), "-") | I32: =IF(ISNUMBER(E32), $M$14, "-") | J32: =IF(ISNUMBER(E32), INT(($D$15*1000)/H32), "-") | K32: =IF(ISNUMBER(E32), MIN(I32, J32), "-") | L32: =IF(ISNUMBER(E32), ROUND((K32*H32)/1000, 2), "-") | M32: =IF(ISNUMBER(E32), L32/$D$15, "-") | N32: =IF(NOT(ISNUMBER(E32)), "-", IF(J32<=I32, "Weight Limited", "Volume Limited"))
A33: 60 | B33: =IF(ISNUMBER(E33), "Available", "N/A") | C33: =IF(ISNUMBER(E33), $I$11, "-") | D33: =IF(ISNUMBER(E33), ROUND(E33/25.4, 3), "-") | E33: =IFERROR(INDEX('3_ASME_Spec_DB'!$N$12:$N$47, MATCH($D$6, '3_ASME_Spec_DB'!$A$12:$A$47, 0)), "-") | F33: =IF(ISNUMBER(E33), ROUND(C33-2*E33, 2), "-") | G33: =IF(ISNUMBER(E33), ROUND((C33-E33)*E33*$I$15, 3), "-") | H33: =IF(ISNUMBER(E33), ROUND(G33*$D$8, 2), "-") | I33: =IF(ISNUMBER(E33), $M$14, "-") | J33: =IF(ISNUMBER(E33), INT(($D$15*1000)/H33), "-") | K33: =IF(ISNUMBER(E33), MIN(I33, J33), "-") | L33: =IF(ISNUMBER(E33), ROUND((K33*H33)/1000, 2), "-") | M33: =IF(ISNUMBER(E33), L33/$D$15, "-") | N33: =IF(NOT(ISNUMBER(E33)), "-", IF(J33<=I33, "Weight Limited", "Volume Limited"))
A34: 80S | B34: =IF(ISNUMBER(E34), "Available", "N/A") | C34: =IF(ISNUMBER(E34), $I$11, "-") | D34: =IF(ISNUMBER(E34), ROUND(E34/25.4, 3), "-") | E34: =IFERROR(INDEX('3_ASME_Spec_DB'!$O$12:$O$47, MATCH($D$6, '3_ASME_Spec_DB'!$A$12:$A$47, 0)), "-") | F34: =IF(ISNUMBER(E34), ROUND(C34-2*E34, 2), "-") | G34: =IF(ISNUMBER(E34), ROUND((C34-E34)*E34*$I$15, 3), "-") | H34: =IF(ISNUMBER(E34), ROUND(G34*$D$8, 2), "-") | I34: =IF(ISNUMBER(E34), $M$14, "-") | J34: =IF(ISNUMBER(E34), INT(($D$15*1000)/H34), "-") | K34: =IF(ISNUMBER(E34), MIN(I34, J34), "-") | L34: =IF(ISNUMBER(E34), ROUND((K34*H34)/1000, 2), "-") | M34: =IF(ISNUMBER(E34), L34/$D$15, "-") | N34: =IF(NOT(ISNUMBER(E34)), "-", IF(J34<=I34, "Weight Limited", "Volume Limited"))
A35: XS | B35: =IF(ISNUMBER(E35), "Available", "N/A") | C35: =IF(ISNUMBER(E35), $I$11, "-") | D35: =IF(ISNUMBER(E35), ROUND(E35/25.4, 3), "-") | E35: =IFERROR(INDEX('3_ASME_Spec_DB'!$P$12:$P$47, MATCH($D$6, '3_ASME_Spec_DB'!$A$12:$A$47, 0)), "-") | F35: =IF(ISNUMBER(E35), ROUND(C35-2*E35, 2), "-") | G35: =IF(ISNUMBER(E35), ROUND((C35-E35)*E35*$I$15, 3), "-") | H35: =IF(ISNUMBER(E35), ROUND(G35*$D$8, 2), "-") | I35: =IF(ISNUMBER(E35), $M$14, "-") | J35: =IF(ISNUMBER(E35), INT(($D$15*1000)/H35), "-") | K35: =IF(ISNUMBER(E35), MIN(I35, J35), "-") | L35: =IF(ISNUMBER(E35), ROUND((K35*H35)/1000, 2), "-") | M35: =IF(ISNUMBER(E35), L35/$D$15, "-") | N35: =IF(NOT(ISNUMBER(E35)), "-", IF(J35<=I35, "Weight Limited", "Volume Limited"))
A36: 80 | B36: =IF(ISNUMBER(E36), "Available", "N/A") | C36: =IF(ISNUMBER(E36), $I$11, "-") | D36: =IF(ISNUMBER(E36), ROUND(E36/25.4, 3), "-") | E36: =IFERROR(INDEX('3_ASME_Spec_DB'!$Q$12:$Q$47, MATCH($D$6, '3_ASME_Spec_DB'!$A$12:$A$47, 0)), "-") | F36: =IF(ISNUMBER(E36), ROUND(C36-2*E36, 2), "-") | G36: =IF(ISNUMBER(E36), ROUND((C36-E36)*E36*$I$15, 3), "-") | H36: =IF(ISNUMBER(E36), ROUND(G36*$D$8, 2), "-") | I36: =IF(ISNUMBER(E36), $M$14, "-") | J36: =IF(ISNUMBER(E36), INT(($D$15*1000)/H36), "-") | K36: =IF(ISNUMBER(E36), MIN(I36, J36), "-") | L36: =IF(ISNUMBER(E36), ROUND((K36*H36)/1000, 2), "-") | M36: =IF(ISNUMBER(E36), L36/$D$15, "-") | N36: =IF(NOT(ISNUMBER(E36)), "-", IF(J36<=I36, "Weight Limited", "Volume Limited"))
A37: 100 | B37: =IF(ISNUMBER(E37), "Available", "N/A") | C37: =IF(ISNUMBER(E37), $I$11, "-") | D37: =IF(ISNUMBER(E37), ROUND(E37/25.4, 3), "-") | E37: =IFERROR(INDEX('3_ASME_Spec_DB'!$R$12:$R$47, MATCH($D$6, '3_ASME_Spec_DB'!$A$12:$A$47, 0)), "-") | F37: =IF(ISNUMBER(E37), ROUND(C37-2*E37, 2), "-") | G37: =IF(ISNUMBER(E37), ROUND((C37-E37)*E37*$I$15, 3), "-") | H37: =IF(ISNUMBER(E37), ROUND(G37*$D$8, 2), "-") | I37: =IF(ISNUMBER(E37), $M$14, "-") | J37: =IF(ISNUMBER(E37), INT(($D$15*1000)/H37), "-") | K37: =IF(ISNUMBER(E37), MIN(I37, J37), "-") | L37: =IF(ISNUMBER(E37), ROUND((K37*H37)/1000, 2), "-") | M37: =IF(ISNUMBER(E37), L37/$D$15, "-") | N37: =IF(NOT(ISNUMBER(E37)), "-", IF(J37<=I37, "Weight Limited", "Volume Limited"))
A38: 120 | B38: =IF(ISNUMBER(E38), "Available", "N/A") | C38: =IF(ISNUMBER(E38), $I$11, "-") | D38: =IF(ISNUMBER(E38), ROUND(E38/25.4, 3), "-") | E38: =IFERROR(INDEX('3_ASME_Spec_DB'!$S$12:$S$47, MATCH($D$6, '3_ASME_Spec_DB'!$A$12:$A$47, 0)), "-") | F38: =IF(ISNUMBER(E38), ROUND(C38-2*E38, 2), "-") | G38: =IF(ISNUMBER(E38), ROUND((C38-E38)*E38*$I$15, 3), "-") | H38: =IF(ISNUMBER(E38), ROUND(G38*$D$8, 2), "-") | I38: =IF(ISNUMBER(E38), $M$14, "-") | J38: =IF(ISNUMBER(E38), INT(($D$15*1000)/H38), "-") | K38: =IF(ISNUMBER(E38), MIN(I38, J38), "-") | L38: =IF(ISNUMBER(E38), ROUND((K38*H38)/1000, 2), "-") | M38: =IF(ISNUMBER(E38), L38/$D$15, "-") | N38: =IF(NOT(ISNUMBER(E38)), "-", IF(J38<=I38, "Weight Limited", "Volume Limited"))
A39: 140 | B39: =IF(ISNUMBER(E39), "Available", "N/A") | C39: =IF(ISNUMBER(E39), $I$11, "-") | D39: =IF(ISNUMBER(E39), ROUND(E39/25.4, 3), "-") | E39: =IFERROR(INDEX('3_ASME_Spec_DB'!$T$12:$T$47, MATCH($D$6, '3_ASME_Spec_DB'!$A$12:$A$47, 0)), "-") | F39: =IF(ISNUMBER(E39), ROUND(C39-2*E39, 2), "-") | G39: =IF(ISNUMBER(E39), ROUND((C39-E39)*E39*$I$15, 3), "-") | H39: =IF(ISNUMBER(E39), ROUND(G39*$D$8, 2), "-") | I39: =IF(ISNUMBER(E39), $M$14, "-") | J39: =IF(ISNUMBER(E39), INT(($D$15*1000)/H39), "-") | K39: =IF(ISNUMBER(E39), MIN(I39, J39), "-") | L39: =IF(ISNUMBER(E39), ROUND((K39*H39)/1000, 2), "-") | M39: =IF(ISNUMBER(E39), L39/$D$15, "-") | N39: =IF(NOT(ISNUMBER(E39)), "-", IF(J39<=I39, "Weight Limited", "Volume Limited"))
A40: 160 | B40: =IF(ISNUMBER(E40), "Available", "N/A") | C40: =IF(ISNUMBER(E40), $I$11, "-") | D40: =IF(ISNUMBER(E40), ROUND(E40/25.4, 3), "-") | E40: =IFERROR(INDEX('3_ASME_Spec_DB'!$U$12:$U$47, MATCH($D$6, '3_ASME_Spec_DB'!$A$12:$A$47, 0)), "-") | F40: =IF(ISNUMBER(E40), ROUND(C40-2*E40, 2), "-") | G40: =IF(ISNUMBER(E40), ROUND((C40-E40)*E40*$I$15, 3), "-") | H40: =IF(ISNUMBER(E40), ROUND(G40*$D$8, 2), "-") | I40: =IF(ISNUMBER(E40), $M$14, "-") | J40: =IF(ISNUMBER(E40), INT(($D$15*1000)/H40), "-") | K40: =IF(ISNUMBER(E40), MIN(I40, J40), "-") | L40: =IF(ISNUMBER(E40), ROUND((K40*H40)/1000, 2), "-") | M40: =IF(ISNUMBER(E40), L40/$D$15, "-") | N40: =IF(NOT(ISNUMBER(E40)), "-", IF(J40<=I40, "Weight Limited", "Volume Limited"))
A41: XXS | B41: =IF(ISNUMBER(E41), "Available", "N/A") | C41: =IF(ISNUMBER(E41), $I$11, "-") | D41: =IF(ISNUMBER(E41), ROUND(E41/25.4, 3), "-") | E41: =IFERROR(INDEX('3_ASME_Spec_DB'!$V$12:$V$47, MATCH($D$6, '3_ASME_Spec_DB'!$A$12:$A$47, 0)), "-") | F41: =IF(ISNUMBER(E41), ROUND(C41-2*E41, 2), "-") | G41: =IF(ISNUMBER(E41), ROUND((C41-E41)*E41*$I$15, 3), "-") | H41: =IF(ISNUMBER(E41), ROUND(G41*$D$8, 2), "-") | I41: =IF(ISNUMBER(E41), $M$14, "-") | J41: =IF(ISNUMBER(E41), INT(($D$15*1000)/H41), "-") | K41: =IF(ISNUMBER(E41), MIN(I41, J41), "-") | L41: =IF(ISNUMBER(E41), ROUND((K41*H41)/1000, 2), "-") | M41: =IF(ISNUMBER(E41), L41/$D$15, "-") | N41: =IF(NOT(ISNUMBER(E41)), "-", IF(J41<=I41, "Weight Limited", "Volume Limited"))

Sheet 2_Selectable_Master_Table
A1: PRECISE PIPE — 40GP CONTAINER LOADING MASTER SELECTABLE TABLE (ALL NPS & SCHEDULES)
A2: Use column filter dropdowns (Row 10) to filter by Material (Carbon Steel / Stainless Steel), Nominal Pipe Size (NPS 1/8" to 48"), Pipe Schedule, or Bottleneck Type. Yellow cells (Rows 5-8) are interactive parameters.
A4: 40GP CONTAINER DIMENSIONS & WEIGHT LIMIT | E4: EFFECTIVE LOADING SPACE & PIPE LENGTH | I4: PACKING METHOD & MATERIAL FACTORS
A5: 40GP Internal Length (m) | C5: 12.032 | E5: Selected Pipe Length (m) [Input] | G5: 11.8 | I5: Lengthwise Tiers in 40GP | K5: =INT(C5/G5)
A6: 40GP Internal Width (mm) | C6: 2352 | E6: Effective Loading Width (mm) [Input] | G6: 2300 | I6: Cross-Section Stacking [Input] | K6: Staggered (Hexagonal)
A7: 40GP Internal Height (mm) | C7: 2393 | E7: Effective Loading Height (mm) [Input] | G7: 2280 | I7: Carbon Steel Factor C (kg/m) | K7: ='3_ASME_Spec_DB'!D6
A8: Max Container Payload (MT) [Input] | C8: 26 | E8: Max Container Payload (kg) | G8: =C8*1000 | I8: SS304 / SS316 Factor C (kg/m) | K8: ='3_ASME_Spec_DB'!D7 | L8: ='3_ASME_Spec_DB'!D8
A10: ID | B10: Material | C10: Standard | D10: NPS (in) | E10: DN (mm) | F10: Schedule | G10: OD (in) | H10: OD (mm) | I10: WT (in) | J10: WT (mm) | K10: Unit Weight (kg/m) | L10: Piece Weight (kg/pc) | M10: Horiz. Fit (pcs/row) | N10: Vert. Layers (rows) | O10: Max Pieces by Volume | P10: Max Pieces by Weight | Q10: 40GP Actual Pieces (pcs) | R10: 40GP Actual Metric Tons (MT) | S10: Payload Util. (%) | T10: Space Slot Util. (%) | U10: Limiting Factor (Bottleneck)
A11: 1 | B11: Carbon Steel | C11: ASME B36.10M | D11: 1/8'' | E11: 6 | F11: 10 | G11: 0.405 | H11: 10.29 | I11: 0.049 | J11: 1.24 | K11: =ROUND((H11-J11)*J11*IF(B11="Carbon Steel",$K$7,IF(B11="Stainless Steel 304",$K$8,$L$8)), 3) | L11: =ROUND(K11*$G$5, 2) | M11: =INT($G$6/H11) | N11: =IF(M11=0, 0, IF(OR($K$6="Square Grid", M11=1), INT($G$7/H11), IF($G$7<H11, 0, 1+INT(($G$7-H11)/(0.8660254*H11))))) | O11: =IF(OR(M11=0,N11=0), 0, IF(OR($K$6="Square Grid", M11=1), M11*N11*$K$5, (INT((N11+1)/2)*M11 + INT(N11/2)*IF(($G$6-M11*H11)>=0.5*H11, M11, M11-1))*$K$5)) | P11: =IF(L11<=0, 0, INT($G$8/L11)) | Q11: =MIN(O11, P11) | R11: =ROUND((Q11*L11)/1000, 2) | S11: =IF($C$8>0, R11/$C$8, 0) | T11: =IF(O11>0, Q11/O11, 0) | U11: =IF(Q11=0, "Exceeds Limit", IF(P11<=O11, "Weight Limited", "Volume Limited"))
A12: 2 | B12: Carbon Steel | C12: ASME B36.10M | D12: 1/8'' | E12: 6 | F12: 30 | G12: 0.405 | H12: 10.29 | I12: 0.057 | J12: 1.45 | K12: =ROUND((H12-J12)*J12*IF(B12="Carbon Steel",$K$7,IF(B12="Stainless Steel 304",$K$8,$L$8)), 3) | L12: =ROUND(K12*$G$5, 2) | M12: =INT($G$6/H12) | N12: =IF(M12=0, 0, IF(OR($K$6="Square Grid", M12=1), INT($G$7/H12), IF($G$7<H12, 0, 1+INT(($G$7-H12)/(0.8660254*H12))))) | O12: =IF(OR(M12=0,N12=0), 0, IF(OR($K$6="Square Grid", M12=1), M12*N12*$K$5, (INT((N12+1)/2)*M12 + INT(N12/2)*IF(($G$6-M12*H12)>=0.5*H12, M12, M12-1))*$K$5)) | P12: =IF(L12<=0, 0, INT($G$8/L12)) | Q12: =MIN(O12, P12) | R12: =ROUND((Q12*L12)/1000, 2) | S12: =IF($C$8>0, R12/$C$8, 0) | T12: =IF(O12>0, Q12/O12, 0) | U12: =IF(Q12=0, "Exceeds Limit", IF(P12<=O12, "Weight Limited", "Volume Limited"))
A13: 3 | B13: Carbon Steel | C13: ASME B36.10M | D13: 1/8'' | E13: 6 | F13: STD | G13: 0.405 | H13: 10.29 | I13: 0.068 | J13: 1.73 | K13: =ROUND((H13-J13)*J13*IF(B13="Carbon Steel",$K$7,IF(B13="Stainless Steel 304",$K$8,$L$8)), 3) | L13: =ROUND(K13*$G$5, 2) | M13: =INT($G$6/H13) | N13: =IF(M13=0, 0, IF(OR($K$6="Square Grid", M13=1), INT($G$7/H13), IF($G$7<H13, 0, 1+INT(($G$7-H13)/(0.8660254*H13))))) | O13: =IF(OR(M13=0,N13=0), 0, IF(OR($K$6="Square Grid", M13=1), M13*N13*$K$5, (INT((N13+1)/2)*M13 + INT(N13/2)*IF(($G$6-M13*H13)>=0.5*H13, M13, M13-1))*$K$5)) | P13: =IF(L13<=0, 0, INT($G$8/L13)) | Q13: =MIN(O13, P13) | R13: =ROUND((Q13*L13)/1000, 2) | S13: =IF($C$8>0, R13/$C$8, 0) | T13: =IF(O13>0, Q13/O13, 0) | U13: =IF(Q13=0, "Exceeds Limit", IF(P13<=O13, "Weight Limited", "Volume Limited"))
A14: 4 | B14: Carbon Steel | C14: ASME B36.10M | D14: 1/8'' | E14: 6 | F14: 40 | G14: 0.405 | H14: 10.29 | I14: 0.068 | J14: 1.73 | K14: =ROUND((H14-J14)*J14*IF(B14="Carbon Steel",$K$7,IF(B14="Stainless Steel 304",$K$8,$L$8)), 3) | L14: =ROUND(K14*$G$5, 2) | M14: =INT($G$6/H14) | N14: =IF(M14=0, 0, IF(OR($K$6="Square Grid", M14=1), INT($G$7/H14), IF($G$7<H14, 0, 1+INT(($G$7-H14)/(0.8660254*H14))))) | O14: =IF(OR(M14=0,N14=0), 0, IF(OR($K$6="Square Grid", M14=1), M14*N14*$K$5, (INT((N14+1)/2)*M14 + INT(N14/2)*IF(($G$6-M14*H14)>=0.5*H14, M14, M14-1))*$K$5)) | P14: =IF(L14<=0, 0, INT($G$8/L14)) | Q14: =MIN(O14, P14) | R14: =ROUND((Q14*L14)/1000, 2) | S14: =IF($C$8>0, R14/$C$8, 0) | T14: =IF(O14>0, Q14/O14, 0) | U14: =IF(Q14=0, "Exceeds Limit", IF(P14<=O14, "Weight Limited", "Volume Limited"))
A15: 5 | B15: Carbon Steel | C15: ASME B36.10M | D15: 1/8'' | E15: 6 | F15: XS | G15: 0.405 | H15: 10.29 | I15: 0.095 | J15: 2.41 | K15: =ROUND((H15-J15)*J15*IF(B15="Carbon Steel",$K$7,IF(B15="Stainless Steel 304",$K$8,$L$8)), 3) | L15: =ROUND(K15*$G$5, 2) | M15: =INT($G$6/H15) | N15: =IF(M15=0, 0, IF(OR($K$6="Square Grid", M15=1), INT($G$7/H15), IF($G$7<H15, 0, 1+INT(($G$7-H15)/(0.8660254*H15))))) | O15: =IF(OR(M15=0,N15=0), 0, IF(OR($K$6="Square Grid", M15=1), M15*N15*$K$5, (INT((N15+1)/2)*M15 + INT(N15/2)*IF(($G$6-M15*H15)>=0.5*H15, M15, M15-1))*$K$5)) | P15: =IF(L15<=0, 0, INT($G$8/L15)) | Q15: =MIN(O15, P15) | R15: =ROUND((Q15*L15)/1000, 2) | S15: =IF($C$8>0, R15/$C$8, 0) | T15: =IF(O15>0, Q15/O15, 0) | U15: =IF(Q15=0, "Exceeds Limit", IF(P15<=O15, "Weight Limited", "Volume Limited"))
A16: 6 | B16: Carbon Steel | C16: ASME B36.10M | D16: 1/8'' | E16: 6 | F16: 80 | G16: 0.405 | H16: 10.29 | I16: 0.095 | J16: 2.41 | K16: =ROUND((H16-J16)*J16*IF(B16="Carbon Steel",$K$7,IF(B16="Stainless Steel 304",$K$8,$L$8)), 3) | L16: =ROUND(K16*$G$5, 2) | M16: =INT($G$6/H16) | N16: =IF(M16=0, 0, IF(OR($K$6="Square Grid", M16=1), INT($G$7/H16), IF($G$7<H16, 0, 1+INT(($G$7-H16)/(0.8660254*H16))))) | O16: =IF(OR(M16=0,N16=0), 0, IF(OR($K$6="Square Grid", M16=1), M16*N16*$K$5, (INT((N16+1)/2)*M16 + INT(N16/2)*IF(($G$6-M16*H16)>=0.5*H16, M16, M16-1))*$K$5)) | P16: =IF(L16<=0, 0, INT($G$8/L16)) | Q16: =MIN(O16, P16) | R16: =ROUND((Q16*L16)/1000, 2) | S16: =IF($C$8>0, R16/$C$8, 0) | T16: =IF(O16>0, Q16/O16, 0) | U16: =IF(Q16=0, "Exceeds Limit", IF(P16<=O16, "Weight Limited", "Volume Limited"))
A17: 7 | B17: Carbon Steel | C17: ASME B36.10M | D17: 1/4'' | E17: 8 | F17: 10 | G17: 0.54 | H17: 13.72 | I17: 0.065 | J17: 1.65 | K17: =ROUND((H17-J17)*J17*IF(B17="Carbon Steel",$K$7,IF(B17="Stainless Steel 304",$K$8,$L$8)), 3) | L17: =ROUND(K17*$G$5, 2) | M17: =INT($G$6/H17) | N17: =IF(M17=0, 0, IF(OR($K$6="Square Grid", M17=1), INT($G$7/H17), IF($G$7<H17, 0, 1+INT(($G$7-H17)/(0.8660254*H17))))) | O17: =IF(OR(M17=0,N17=0), 0, IF(OR($K$6="Square Grid", M17=1), M17*N17*$K$5, (INT((N17+1)/2)*M17 + INT(N17/2)*IF(($G$6-M17*H17)>=0.5*H17, M17, M17-1))*$K$5)) | P17: =IF(L17<=0, 0, INT($G$8/L17)) | Q17: =MIN(O17, P17) | R17: =ROUND((Q17*L17)/1000, 2) | S17: =IF($C$8>0, R17/$C$8, 0) | T17: =IF(O17>0, Q17/O17, 0) | U17: =IF(Q17=0, "Exceeds Limit", IF(P17<=O17, "Weight Limited", "Volume Limited"))
A18: 8 | B18: Carbon Steel | C18: ASME B36.10M | D18: 1/4'' | E18: 8 | F18: 30 | G18: 0.54 | H18: 13.72 | I18: 0.073 | J18: 1.85 | K18: =ROUND((H18-J18)*J18*IF(B18="Carbon Steel",$K$7,IF(B18="Stainless Steel 304",$K$8,$L$8)), 3) | L18: =ROUND(K18*$G$5, 2) | M18: =INT($G$6/H18) | N18: =IF(M18=0, 0, IF(OR($K$6="Square Grid", M18=1), INT($G$7/H18), IF($G$7<H18, 0, 1+INT(($G$7-H18)/(0.8660254*H18))))) | O18: =IF(OR(M18=0,N18=0), 0, IF(OR($K$6="Square Grid", M18=1), M18*N18*$K$5, (INT((N18+1)/2)*M18 + INT(N18/2)*IF(($G$6-M18*H18)>=0.5*H18, M18, M18-1))*$K$5)) | P18: =IF(L18<=0, 0, INT($G$8/L18)) | Q18: =MIN(O18, P18) | R18: =ROUND((Q18*L18)/1000, 2) | S18: =IF($C$8>0, R18/$C$8, 0) | T18: =IF(O18>0, Q18/O18, 0) | U18: =IF(Q18=0, "Exceeds Limit", IF(P18<=O18, "Weight Limited", "Volume Limited"))
A19: 9 | B19: Carbon Steel | C19: ASME B36.10M | D19: 1/4'' | E19: 8 | F19: STD | G19: 0.54 | H19: 13.72 | I19: 0.088 | J19: 2.24 | K19: =ROUND((H19-J19)*J19*IF(B19="Carbon Steel",$K$7,IF(B19="Stainless Steel 304",$K$8,$L$8)), 3) | L19: =ROUND(K19*$G$5, 2) | M19: =INT($G$6/H19) | N19: =IF(M19=0, 0, IF(OR($K$6="Square Grid", M19=1), INT($G$7/H19), IF($G$7<H19, 0, 1+INT(($G$7-H19)/(0.8660254*H19))))) | O19: =IF(OR(M19=0,N19=0), 0, IF(OR($K$6="Square Grid", M19=1), M19*N19*$K$5, (INT((N19+1)/2)*M19 + INT(N19/2)*IF(($G$6-M19*H19)>=0.5*H19, M19, M19-1))*$K$5)) | P19: =IF(L19<=0, 0, INT($G$8/L19)) | Q19: =MIN(O19, P19) | R19: =ROUND((Q19*L19)/1000, 2) | S19: =IF($C$8>0, R19/$C$8, 0) | T19: =IF(O19>0, Q19/O19, 0) | U19: =IF(Q19=0, "Exceeds Limit", IF(P19<=O19, "Weight Limited", "Volume Limited"))
A20: 10 | B20: Carbon Steel | C20: ASME B36.10M | D20: 1/4'' | E20: 8 | F20: 40 | G20: 0.54 | H20: 13.72 | I20: 0.088 | J20: 2.24 | K20: =ROUND((H20-J20)*J20*IF(B20="Carbon Steel",$K$7,IF(B20="Stainless Steel 304",$K$8,$L$8)), 3) | L20: =ROUND(K20*$G$5, 2) | M20: =INT($G$6/H20) | N20: =IF(M20=0, 0, IF(OR($K$6="Square Grid", M20=1), INT($G$7/H20), IF($G$7<H20, 0, 1+INT(($G$7-H20)/(0.8660254*H20))))) | O20: =IF(OR(M20=0,N20=0), 0, IF(OR($K$6="Square Grid", M20=1), M20*N20*$K$5, (INT((N20+1)/2)*M20 + INT(N20/2)*IF(($G$6-M20*H20)>=0.5*H20, M20, M20-1))*$K$5)) | P20: =IF(L20<=0, 0, INT($G$8/L20)) | Q20: =MIN(O20, P20) | R20: =ROUND((Q20*L20)/1000, 2) | S20: =IF($C$8>0, R20/$C$8, 0) | T20: =IF(O20>0, Q20/O20, 0) | U20: =IF(Q20=0, "Exceeds Limit", IF(P20<=O20, "Weight Limited", "Volume Limited"))
A21: 11 | B21: Carbon Steel | C21: ASME B36.10M | D21: 1/4'' | E21: 8 | F21: XS | G21: 0.54 | H21: 13.72 | I21: 0.119 | J21: 3.02 | K21: =ROUND((H21-J21)*J21*IF(B21="Carbon Steel",$K$7,IF(B21="Stainless Steel 304",$K$8,$L$8)), 3) | L21: =ROUND(K21*$G$5, 2) | M21: =INT($G$6/H21) | N21: =IF(M21=0, 0, IF(OR($K$6="Square Grid", M21=1), INT($G$7/H21), IF($G$7<H21, 0, 1+INT(($G$7-H21)/(0.8660254*H21))))) | O21: =IF(OR(M21=0,N21=0), 0, IF(OR($K$6="Square Grid", M21=1), M21*N21*$K$5, (INT((N21+1)/2)*M21 + INT(N21/2)*IF(($G$6-M21*H21)>=0.5*H21, M21, M21-1))*$K$5)) | P21: =IF(L21<=0, 0, INT($G$8/L21)) | Q21: =MIN(O21, P21) | R21: =ROUND((Q21*L21)/1000, 2) | S21: =IF($C$8>0, R21/$C$8, 0) | T21: =IF(O21>0, Q21/O21, 0) | U21: =IF(Q21=0, "Exceeds Limit", IF(P21<=O21, "Weight Limited", "Volume Limited"))
A22: 12 | B22: Carbon Steel | C22: ASME B36.10M | D22: 1/4'' | E22: 8 | F22: 80 | G22: 0.54 | H22: 13.72 | I22: 0.119 | J22: 3.02 | K22: =ROUND((H22-J22)*J22*IF(B22="Carbon Steel",$K$7,IF(B22="Stainless Steel 304",$K$8,$L$8)), 3) | L22: =ROUND(K22*$G$5, 2) | M22: =INT($G$6/H22) | N22: =IF(M22=0, 0, IF(OR($K$6="Square Grid", M22=1), INT($G$7/H22), IF($G$7<H22, 0, 1+INT(($G$7-H22)/(0.8660254*H22))))) | O22: =IF(OR(M22=0,N22=0), 0, IF(OR($K$6="Square Grid", M22=1), M22*N22*$K$5, (INT((N22+1)/2)*M22 + INT(N22/2)*IF(($G$6-M22*H22)>=0.5*H22, M22, M22-1))*$K$5)) | P22: =IF(L22<=0, 0, INT($G$8/L22)) | Q22: =MIN(O22, P22) | R22: =ROUND((Q22*L22)/1000, 2) | S22: =IF($C$8>0, R22/$C$8, 0) | T22: =IF(O22>0, Q22/O22, 0) | U22: =IF(Q22=0, "Exceeds Limit", IF(P22<=O22, "Weight Limited", "Volume Limited"))
... A717: 707 | B717: Stainless Steel 316 | C717: ASME B36.19M | D717: 48'' | E717: 1200 | F717: XS | G717: 48 | H717: 1219.2 | I717: 0.5 | J717: 12.7 | K717: =ROUND((H717-J717)*J717*IF(B717="Carbon Steel",$K$7,IF(B717="Stainless Steel 304",$K$8,$L$8)), 3) | L717: =ROUND(K717*$G$5, 2) | M717: =INT($G$6/H717) | N717: =IF(M717=0, 0, IF(OR($K$6="Square Grid", M717=1), INT($G$7/H717), IF($G$7<H717, 0, 1+INT(($G$7-H717)/(0.8660254*H717))))) | O717: =IF(OR(M717=0,N717=0), 0, IF(OR($K$6="Square Grid", M717=1), M717*N717*$K$5, (INT((N717+1)/2)*M717 + INT(N717/2)*IF(($G$6-M717*H717)>=0.5*H717, M717, M717-1))*$K$5)) | P717: =IF(L717<=0, 0, INT($G$8/L717)) | Q717: =MIN(O717, P717) | R717: =ROUND((Q717*L717)/1000, 2) | S717: =IF($C$8>0, R717/$C$8, 0) | T717: =IF(O717>0, Q717/O717, 0) | U717: =IF(Q717=0, "Exceeds Limit", IF(P717<=O717, "Weight Limited", "Volume Limited"))

Sheet 3_ASME_Spec_DB
A1: PRECISE PIPE — ASME B36.10M (CARBON STEEL) & B36.19M (STAINLESS STEEL) ENGINEERING DATABASE
A2: Reference Standard: ASME B36.10M / B36.19M | Nominal Pipe Size (NPS 1/8" to 48") | Outer Diameter (OD) & Wall Thickness (WT) in Millimeters (mm)
A4: ENGINEERING CONSTANTS & MATERIAL DENSITIES
A5: Material Grade | B5: Standard Spec | C5: Density (g/cm3) | D5: Weight Factor C (kg/m) | E5: Formula: Unit Weight (kg/m)
A6: Carbon Steel (CS) | B6: ASME B36.10M / ASTM A53, A106, API 5L | C6: 7.85 | D6: =ROUND(PI()*10^-6*(C6*1000), 7) | E6: (OD_mm - WT_mm) * WT_mm * D6
A7: Stainless Steel 304/304L (SS304) | B7: ASME B36.19M / ASTM A312 TP304 | C7: 7.93 | D7: =ROUND(PI()*10^-6*(C7*1000), 7) | E7: (OD_mm - WT_mm) * WT_mm * D7
A8: Stainless Steel 316/316L (SS316) | B8: ASME B36.19M / ASTM A312 TP316 | C8: 7.98 | D8: =ROUND(PI()*10^-6*(C8*1000), 7) | E8: (OD_mm - WT_mm) * WT_mm * D8
A10: MASTER PIPE SCHEDULE CHART — WALL THICKNESS IN MILLIMETERS (MM)
A11: NPS (in) | B11: DN (mm) | C11: OD (in) | D11: OD (mm) | E11: Sch 5S | F11: Sch 5 | G11: Sch 10S | H11: Sch 10 | I11: Sch 20 | J11: Sch 30 | K11: Sch 40S | L11: Sch STD | M11: Sch 40 | N11: Sch 60 | O11: Sch 80S | P11: Sch XS | Q11: Sch 80 | R11: Sch 100 | S11: Sch 120 | T11: Sch 140 | U11: Sch 160 | V11: Sch XXS
A12: 1/8'' | B12: 6 | C12: 0.405 | D12: 10.29 | E12: - | F12: - | G12: 1.24 | H12: 1.24 | I12: - | J12: 1.45 | K12: 1.73 | L12: 1.73 | M12: 1.73 | N12: - | O12: 2.41 | P12: 2.41 | Q12: 2.41 | R12: - | S12: - | T12: - | U12: - | V12: -
A13: 1/4'' | B13: 8 | C13: 0.54 | D13: 13.72 | E13: - | F13: - | G13: 1.65 | H13: 1.65 | I13: - | J13: 1.85 | K13: 2.24 | L13: 2.24 | M13: 2.24 | N13: - | O13: 3.02 | P13: 3.02 | Q13: 3.02 | R13: - | S13: - | T13: - | U13: - | V13: -
A14: 3/8'' | B14: 10 | C14: 0.675 | D14: 17.14 | E14: - | F14: - | G14: 1.65 | H14: 1.65 | I14: - | J14: 1.85 | K14: 2.31 | L14: 2.31 | M14: 2.31 | N14: - | O14: 3.2 | P14: 3.2 | Q14: 3.2 | R14: - | S14: - | T14: - | U14: - | V14: -
A15: 1/2'' | B15: 15 | C15: 0.84 | D15: 21.34 | E15: 1.65 | F15: 1.65 | G15: 2.11 | H15: 2.11 | I15: - | J15: 2.41 | K15: 2.77 | L15: 2.77 | M15: 2.77 | N15: - | O15: 3.73 | P15: 3.73 | Q15: 3.73 | R15: - | S15: - | T15: - | U15: 4.78 | V15: 7.47
A16: 3/4'' | B16: 20 | C16: 1.05 | D16: 26.67 | E16: 1.65 | F16: 1.65 | G16: 2.11 | H16: 2.11 | I16: - | J16: 2.41 | K16: 2.87 | L16: 2.87 | M16: 2.87 | N16: - | O16: 3.91 | P16: 3.91 | Q16: 3.91 | R16: - | S16: - | T16: - | U16: 5.56 | V16: 7.82
A17: 1'' | B17: 25 | C17: 1.315 | D17: 33.4 | E17: 1.65 | F17: 1.65 | G17: 2.77 | H17: 2.77 | I17: - | J17: 2.9 | K17: 3.38 | L17: 3.38 | M17: 3.38 | N17: - | O17: 4.55 | P17: 4.55 | Q17: 4.55 | R17: - | S17: - | T17: - | U17: 6.35 | V17: 9.09
A18: 1-1/4'' | B18: 32 | C18: 1.66 | D18: 42.16 | E18: 1.65 | F18: 1.65 | G18: 2.77 | H18: 2.77 | I18: - | J18: 2.97 | K18: 3.56 | L18: 3.56 | M18: 3.56 | N18: - | O18: 4.85 | P18: 4.85 | Q18: 4.85 | R18: - | S18: - | T18: - | U18: 6.35 | V18: 9.7
A19: 1-1/2'' | B19: 40 | C19: 1.9 | D19: 48.26 | E19: 1.65 | F19: 1.65 | G19: 2.77 | H19: 2.77 | I19: - | J19: 3.17 | K19: 3.68 | L19: 3.68 | M19: 3.68 | N19: - | O19: 5.08 | P19: 5.08 | Q19: 5.08 | R19: - | S19: - | T19: - | U19: 7.14 | V19: 10.16
A20: 2'' | B20: 50 | C20: 2.375 | D20: 60.32 | E20: 1.65 | F20: 1.65 | G20: 2.77 | H20: 2.77 | I20: - | J20: 3.17 | K20: 3.91 | L20: 3.91 | M20: 3.91 | N20: - | O20: 5.54 | P20: 5.54 | Q20: 5.54 | R20: - | S20: - | T20: - | U20: 8.74 | V20: 11.07
A21: 2-1/2'' | B21: 65 | C21: 2.875 | D21: 73.02 | E21: 2.11 | F21: 2.11 | G21: 3.05 | H21: 3.05 | I21: - | J21: 4.78 | K21: 5.16 | L21: 5.16 | M21: 5.16 | N21: - | O21: 7.01 | P21: 7.01 | Q21: 7.01 | R21: - | S21: - | T21: - | U21: 9.52 | V21: 14.02
A22: 3'' | B22: 80 | C22: 3.5 | D22: 88.9 | E22: 2.11 | F22: 2.11 | G22: 3.05 | H22: 3.05 | I22: - | J22: 4.78 | K22: 5.49 | L22: 5.49 | M22: 5.49 | N22: - | O22: 7.62 | P22: 7.62 | Q22: 7.62 | R22: - | S22: - | T22: - | U22: 11.13 | V22: 15.24
A23: 3-1/2'' | B23: 90 | C23: 4 | D23: 101.6 | E23: 2.11 | F23: 2.11 | G23: 3.05 | H23: 3.05 | I23: - | J23: 4.78 | K23: 5.74 | L23: 5.74 | M23: 5.74 | N23: - | O23: 8.08 | P23: 8.08 | Q23: 8.08 | R23: - | S23: - | T23: - | U23: - | V23: 16.15
A24: 4'' | B24: 100 | C24: 4.5 | D24: 114.3 | E24: 2.11 | F24: 2.11 | G24: 3.05 | H24: 3.05 | I24: - | J24: 4.78 | K24: 6.02 | L24: 6.02 | M24: 6.02 | N24: 7.14 | O24: 8.56 | P24: 8.56 | Q24: 8.56 | R24: - | S24: 11.13 | T24: - | U24: 13.49 | V24: 17.12
A25: 5'' | B25: 125 | C25: 5.563 | D25: 141.3 | E25: 2.77 | F25: 2.77 | G25: 3.4 | H25: 3.4 | I25: - | J25: - | K25: 6.55 | L25: 6.55 | M25: 6.55 | N25: - | O25: 9.52 | P25: 9.52 | Q25: 9.52 | R25: - | S25: 12.7 | T25: - | U25: 15.88 | V25: 19.05
A26: 6'' | B26: 150 | C26: 6.625 | D26: 168.27 | E26: 2.77 | F26: 2.77 | G26: 3.4 | H26: 3.4 | I26: - | J26: - | K26: 7.11 | L26: 7.11 | M26: 7.11 | N26: - | O26: 10.97 | P26: 10.97 | Q26: 10.97 | R26: - | S26: 14.27 | T26: - | U26: 18.26 | V26: 21.95
A27: 8'' | B27: 200 | C27: 8.625 | D27: 219.07 | E27: 2.77 | F27: 2.77 | G27: 3.76 | H27: 3.76 | I27: 6.35 | J27: 7.04 | K27: 8.18 | L27: 8.18 | M27: 8.18 | N27: 10.31 | O27: 12.7 | P27: 12.7 | Q27: 12.7 | R27: 15.09 | S27: 18.26 | T27: 20.62 | U27: 23.01 | V27: 22.22
A28: 10'' | B28: 250 | C28: 10.75 | D28: 273.05 | E28: 3.4 | F28: 3.4 | G28: 4.19 | H28: 4.19 | I28: 6.35 | J28: 7.8 | K28: 9.27 | L28: 9.27 | M28: 9.27 | N28: 12.7 | O28: 12.7 | P28: 12.7 | Q28: 15.09 | R28: 18.26 | S28: 21.44 | T28: 25.4 | U28: 28.57 | V28: 25.4
A29: 12'' | B29: 300 | C29: 12.75 | D29: 323.85 | E29: 3.96 | F29: 3.96 | G29: 4.57 | H29: 4.57 | I29: 6.35 | J29: 8.38 | K29: 9.52 | L29: 9.52 | M29: 10.31 | N29: 14.27 | O29: 12.7 | P29: 12.7 | Q29: 17.48 | R29: 21.44 | S29: 25.4 | T29: 28.57 | U29: 33.32 | V29: 25.4
A30: 14'' | B30: 350 | C30: 14 | D30: 355.6 | E30: 3.96 | F30: 3.96 | G30: 4.78 | H30: 6.35 | I30: 7.92 | J30: 9.52 | K30: 9.52 | L30: 9.52 | M30: 11.13 | N30: 15.09 | O30: 12.7 | P30: 12.7 | Q30: 19.05 | R30: 23.83 | S30: 27.79 | T30: 31.75 | U30: 35.71 | V30: -
A31: 16'' | B31: 400 | C31: 16 | D31: 406.4 | E31: 4.19 | F31: 4.19 | G31: 4.78 | H31: 6.35 | I31: 7.92 | J31: 9.52 | K31: 9.52 | L31: 9.52 | M31: 12.7 | N31: 16.66 | O31: 12.7 | P31: 12.7 | Q31: 21.44 | R31: 26.19 | S31: 30.96 | T31: 36.53 | U31: 40.49 | V31: -
A32: 18'' | B32: 450 | C32: 18 | D32: 457.2 | E32: 4.19 | F32: 4.19 | G32: 4.78 | H32: 6.35 | I32: 7.92 | J32: 11.13 | K32: 9.52 | L32: 9.52 | M32: 14.27 | N32: 19.05 | O32: 12.7 | P32: 12.7 | Q32: 23.83 | R32: 29.36 | S32: 34.92 | T32: 39.67 | U32: 45.24 | V32: -
A33: 20'' | B33: 500 | C33: 20 | D33: 508 | E33: 4.78 | F33: 4.78 | G33: 5.54 | H33: 6.35 | I33: 9.52 | J33: 12.7 | K33: 9.52 | L33: 9.52 | M33: 15.09 | N33: 20.62 | O33: 12.7 | P33: 12.7 | Q33: 26.19 | R33: 32.54 | S33: 38.1 | T33: 44.45 | U33: 50.01 | V33: -
A34: 22'' | B34: 550 | C34: 22 | D34: 558.8 | E34: 4.78 | F34: 4.78 | G34: 5.54 | H34: 6.35 | I34: 9.52 | J34: 12.7 | K34: 9.52 | L34: 9.52 | M34: - | N34: 22.22 | O34: 12.7 | P34: 12.7 | Q34: 28.57 | R34: 34.92 | S34: 41.27 | T34: 47.62 | U34: 53.97 | V34: -
A35: 24'' | B35: 600 | C35: 24 | D35: 609.6 | E35: 5.54 | F35: 5.54 | G35: 6.35 | H35: 6.35 | I35: 9.52 | J35: 14.27 | K35: 9.52 | L35: 9.52 | M35: 17.48 | N35: 24.61 | O35: 12.7 | P35: 12.7 | Q35: 30.96 | R35: 38.89 | S35: 46.02 | T35: 52.37 | U35: 59.54 | V35: -
A36: 26'' | B36: 650 | C36: 26 | D36: 660.4 | E36: - | F36: - | G36: - | H36: 7.92 | I36: 12.7 | J36: - | K36: - | L36: 9.52 | M36: - | N36: - | O36: - | P36: 12.7 | Q36: - | R36: - | S36: - | T36: - | U36: - | V36: -
A37: 28'' | B37: 700 | C37: 28 | D37: 711.2 | E37: - | F37: - | G37: - | H37: 7.92 | I37: 12.7 | J37: 15.88 | K37: - | L37: 9.52 | M37: - | N37: - | O37: - | P37: 12.7 | Q37: - | R37: - | S37: - | T37: - | U37: - | V37: -
A38: 30'' | B38: 750 | C38: 30 | D38: 762 | E38: 6.35 | F38: 6.35 | G38: 7.92 | H38: 7.92 | I38: 12.7 | J38: 15.88 | K38: 9.52 | L38: 9.52 | M38: - | N38: - | O38: 12.7 | P38: 12.7 | Q38: - | R38: - | S38: - | T38: - | U38: - | V38: -
A39: 32'' | B39: 800 | C39: 32 | D39: 812.8 | E39: - | F39: - | G39: - | H39: 7.92 | I39: 12.7 | J39: 15.88 | K39: - | L39: 9.52 | M39: 17.48 | N39: - | O39: - | P39: 12.7 | Q39: - | R39: - | S39: - | T39: - | U39: - | V39: -
A40: 34'' | B40: 850 | C40: 34 | D40: 863.6 | E40: - | F40: - | G40: - | H40: 7.92 | I40: 12.7 | J40: 15.88 | K40: - | L40: 9.52 | M40: 17.48 | N40: - | O40: - | P40: 12.7 | Q40: - | R40: - | S40: - | T40: - | U40: - | V40: -
A41: 36'' | B41: 900 | C41: 36 | D41: 914.4 | E41: - | F41: - | G41: - | H41: 7.92 | I41: 12.7 | J41: 15.88 | K41: 9.52 | L41: 9.52 | M41: 19.05 | N41: - | O41: 12.7 | P41: 12.7 | Q41: - | R41: - | S41: - | T41: - | U41: - | V41: -
A42: 38'' | B42: 950 | C42: 38 | D42: 965.2 | E42: - | F42: - | G42: - | H42: - | I42: - | J42: - | K42: - | L42: 9.52 | M42: - | N42: - | O42: - | P42: 12.7 | Q42: - | R42: - | S42: - | T42: - | U42: - | V42: -
...
